// example 
async function usingTryCatch() {
  try {
    let resolveValue = await asyncFunction('thing that will fail');
    let secondValue = await secondAsyncFunction(resolveValue);
  } catch (err) {
    // Catches any errors in the try block
    console.log(err);
  }
 }
 
 usingTryCatch();

// we can still use native promiseâ€™s .catch() with an async function
// This is sometimes used in the global scope to catch final errors in complex code.
 async function usingPromiseCatch() {
  let resolveValue = await asyncFunction('thing that will fail');
}

let rejectedPromise = usingPromiseCatch();
rejectedPromise.catch((rejectValue) => {
console.log(rejectValue);
})

// exercise
const cookBeanSouffle = require('./library.js');

async function hostDinnerParty() {
 try {
   let dinner = await cookBeanSouffle();
   console.log(`${dinner} is served!`);
 }
 catch(error){
   console.log(error);
   console.log('Ordering a pizza!');
 }
}

hostDinnerParty();